Workbook

Sheet 202310
A1: 会社名 | D1: ： ＜顧客会社名＞
A2: ご担当者名 | D2: ： ＜顧客ご担当者名＞ | J2: 様
A4: 45292
Q6: ＮＣＤソリューションズ株式会社
A7: 注文No. | D7: ： | E7: Hxxxxx | R7: 業務担当者：＜PL氏名＞
A8: 件名 | D8: ： | E8: IND1-KR4057 Z Tellus IND Ehp適用およびHWリプレース対応
A9: 作業期間 | D9: ： | E9: 2024/1/1～2024/1/31
A10: 提出年月日 | D10: ： | E10: 2024 | F10: 年 | G10: 2 | H10: 月 | I10: 1 | J10: 日
W11: 標準時間 | X11: =#REF!*7.5 -> #REF! | Y11: 下限 | Z11: =X11-20 -> #REF! | AA11: 上限 | AB11: =X11+20 -> #REF!
W12: 勤務日数 | X12: =COUNTA(E17:E47) -> 0
B13: 下記のとおり作業時間をご報告いたします。 | W13: 深夜勤務 | X13: 0.91666667 | Y13: 開始 | Z13: 1.2083333 | AA13: 終了
B14: 担当者： | D14: ＸＸ ＸＸ
A16: 月 | B16: 日 | C16: 曜日 | D16: 区分 | E16: 開 始 | F16: 終 了 | G16: 休憩 時間 | H16: 作業 時間 | I16: 標準 時間 | J16: 標準外 時間 | K16: 深夜 時間 | L16: 休日 時間 | M16: 作業内容 | U16: 休み | W16: 会議
U17: 祝日
U18: 祝日
U19: 祝日
U20: 祝日
U24: 祝日
M25: 15分残業のケース
M26: 深夜対応のケース
M27: 早出のケース
M28: 早出＋残業のケース
A48: 合計 | G48: =SUM(G17:G47) -> 0 | H48: =SUM(H17:H47) -> 0 | I48: =SUM(I17:I47) -> 0 | J48: =SUM(J17:J47) -> 0 | K48: =SUM(K17:K47) -> 0 | L48: =SUM(L17:L47) -> 0 | M48: 月間作業時間 （深夜休日含む） | O48: 深夜 | R48: 休日
O49: 回数 | P49: 時間 | R49: 回数 | S49: 時間
M50: =SUM(I17:L47) -> 0 | O50: =COUNTIF(K17:K47,"<>" & "*") -> 31 | P50: =SUM(K17:K47) -> 0 | R50: =COUNTIF(L17:L47,"<>" & "*") -> 31 | S50: =SUM(L17:L47) -> 0
A51: 【備 考】
N55: 上記作業について確認しました。
N56: 検収印
A63: 4 / 4

Sheet 202310_記入要領
A1: 会社名 | D1: ： ＜顧客会社名＞
A2: ご担当者名 | D2: ： ＜顧客ご担当者名＞ | J2: 様
A4: 45200
R6: 株式会社 ゼクシス
A7: 注文No. | D7: ： | E7: Hxxxxx | R7: 業務担当者：＜PL氏名＞
A8: 件名 | D8: ： | E8: IND1-KR4057 Z Tellus IND Ehp適用およびHWリプレース対応
A9: 作業期間 | D9: ： | E9: 2023/10/1～2023/10/31
A10: 提出年月日 | D10: ： | E10: 2023 | F10: 年 | G10: 11 | H10: 月 | I10: 1 | J10: 日
W11: 標準時間 | X11: =#REF!*7.5 -> #REF! | Y11: 下限 | Z11: =X11-20 -> #REF! | AA11: 上限 | AB11: =X11+20 -> #REF!
W12: 勤務日数 | X12: =COUNTA(E17:E47) -> 22
B13: 下記のとおり作業時間をご報告いたします。 | W13: 深夜勤務 | X13: 0.91666667 | Y13: 開始 | Z13: 1.2083333 | AA13: 終了
B14: 担当者： | D14: ＸＸ ＸＸ
A16: 月 | B16: 日 | C16: 曜日 | D16: 区分 | E16: 開 始 | F16: 終 了 | G16: 休憩 時間 | H16: 作業 時間 | I16: 標準 時間 | J16: 標準外 時間 | K16: 深夜 時間 | L16: 休日 時間 | M16: 作業内容 | U16: 休み | W16: 会議
A17: =B17 -> 45200 | B17: =DATEVALUE(TEXT(A4,"yyyy/mm/") & "01") -> 45200 | C17: =B17 -> 45200 | D17: =IF(U17="稼働","稼働",IF(OR(WEEKDAY(B17)=1,WEEKDAY(B17)=7,C17="日",U17="祝日",U17="特休",U17="代休",U17="休み"),"休日",IF(C17="","","稼働"))) -> 休日 | G17: =IF(AND(E17<>"",F17<>""),IF((F17-E17-マスタ!$B$7)>マスタ!$C$7,マスタ!$B$7,IF((F17-E17-マスタ!$B$6)>マスタ!$C$6,マスタ!$B$6,マスタ!$B$5)),"") | H17: =IF(G17="","",F17-E17-G17) | I17: =IF(D17="休日","",IF(F17>マスタ!$C$2,IF(E17<マスタ!$C$2,マスタ!$C$2-E17-(マスタ!$C$4-マスタ!$C$3),""),IF(E17<マスタ!$C$2,F17-E17-G17,""))) | J17: =IF(D17="休日","",IF(K17="",H17-I17,IF(H17=K17,"",H17-I17-K17))) | K17: =IF(D17="休日","",IF(OR(E17="",F17=""),"",IF(F17>$X$13,IF(F17>$Z$13,$Z$13-$X$13,F17-$X$13),""))) | L17: =IF(D17="休日",H17,"")
B18: =B17+1 -> 45201 | C18: =B18 -> 45201 | D18: =IF(U18="稼働","稼働",IF(OR(WEEKDAY(B18)=1,WEEKDAY(B18)=7,C18="日",U18="祝日",U18="特休",U18="代休",U18="休み"),"休日",IF(C18="","","稼働"))) -> 稼働 | E18: 0.375 | F18: 0.91666667 | G18: =IF(AND(E18<>"",F18<>""),IF((F18-E18-マスタ!$B$7)>マスタ!$C$7,マスタ!$B$7,IF((F18-E18-マスタ!$B$6)>マスタ!$C$6,マスタ!$B$6,マスタ!$B$5)),"") -> 0.041666667 | H18: =IF(G18="","",F18-E18-G18) -> 0.5 | I18: =IF(D18="休日","",IF(F18>マスタ!$C$2,IF(E18<マスタ!$C$2,マスタ!$C$2-E18-(マスタ!$C$4-マスタ!$C$3),""),IF(E18<マスタ!$C$2,F18-E18-G18,""))) -> 0.33333333 | J18: =IF(D18="休日","",IF(K18="",H18-I18,IF(H18=K18,"",H18-I18-K18))) -> 0.16666667 | K18: =IF(D18="休日","",IF(OR(E18="",F18=""),"",IF(F18>$X$13,IF(F18>$Z$13,$Z$13-$X$13,F18-$X$13),""))) | L18: =IF(D18="休日",H18,"") | M18: 例）22時までの残業
B19: =B18+1 -> 45202 | C19: =B19 -> 45202 | D19: =IF(U19="稼働","稼働",IF(OR(WEEKDAY(B19)=1,WEEKDAY(B19)=7,C19="日",U19="祝日",U19="特休",U19="代休",U19="休み"),"休日",IF(C19="","","稼働"))) -> 稼働 | E19: 0.375 | F19: 1.0416667 | G19: =IF(AND(E19<>"",F19<>""),IF((F19-E19-マスタ!$B$7)>マスタ!$C$7,マスタ!$B$7,IF((F19-E19-マスタ!$B$6)>マスタ!$C$6,マスタ!$B$6,マスタ!$B$5)),"") -> 0.041666667 | H19: =IF(G19="","",F19-E19-G19) -> 0.625 | I19: =IF(D19="休日","",IF(F19>マスタ!$C$2,IF(E19<マスタ!$C$2,マスタ!$C$2-E19-(マスタ!$C$4-マスタ!$C$3),""),IF(E19<マスタ!$C$2,F19-E19-G19,""))) -> 0.33333333 | J19: =IF(D19="休日","",IF(K19="",H19-I19,IF(H19=K19,"",H19-I19-K19))) -> 0.16666667 | K19: =IF(D19="休日","",IF(OR(E19="",F19=""),"",IF(F19>$X$13,IF(F19>$Z$13,$Z$13-$X$13,F19-$X$13),""))) -> 0.125 | L19: =IF(D19="休日",H19,"") | M19: 例）深夜1:00までの残業
B20: =B19+1 -> 45203 | C20: =B20 -> 45203 | D20: =IF(U20="稼働","稼働",IF(OR(WEEKDAY(B20)=1,WEEKDAY(B20)=7,C20="日",U20="祝日",U20="特休",U20="代休",U20="休み"),"休日",IF(C20="","","稼働"))) -> 稼働 | E20: 0.375 | F20: 1.15625 | G20: =IF(AND(E20<>"",F20<>""),IF((F20-E20-マスタ!$B$7)>マスタ!$C$7,マスタ!$B$7,IF((F20-E20-マスタ!$B$6)>マスタ!$C$6,マスタ!$B$6,マスタ!$B$5)),"") -> 0.041666667 | H20: =IF(G20="","",F20-E20-G20) -> 0.73958333 | I20: =IF(D20="休日","",IF(F20>マスタ!$C$2,IF(E20<マスタ!$C$2,マスタ!$C$2-E20-(マスタ!$C$4-マスタ!$C$3),""),IF(E20<マスタ!$C$2,F20-E20-G20,""))) -> 0.33333333 | J20: =IF(D20="休日","",IF(K20="",H20-I20,IF(H20=K20,"",H20-I20-K20))) -> 0.16666667 | K20: =IF(D20="休日","",IF(OR(E20="",F20=""),"",IF(F20>$X$13,IF(F20>$Z$13,$Z$13-$X$13,F20-$X$13),""))) -> 0.23958333 | L20: =IF(D20="休日",H20,"") | M20: 例）深夜3:45までの残業
B21: =B20+1 -> 45204 | C21: =B21 -> 45204 | D21: =IF(U21="稼働","稼働",IF(OR(WEEKDAY(B21)=1,WEEKDAY(B21)=7,C21="日",U21="祝日",U21="特休",U21="代休",U21="休み"),"休日",IF(C21="","","稼働"))) -> 稼働 | E21: 0.375 | F21: 0.72916667 | G21: =IF(AND(E21<>"",F21<>""),IF((F21-E21-マスタ!$B$7)>マスタ!$C$7,マスタ!$B$7,IF((F21-E21-マスタ!$B$6)>マスタ!$C$6,マスタ!$B$6,マスタ!$B$5)),"") -> 0.03125 | H21: =IF(G21="","",F21-E21-G21) -> 0.32291667 | I21: =IF(D21="休日","",IF(F21>マスタ!$C$2,IF(E21<マスタ!$C$2,マスタ!$C$2-E21-(マスタ!$C$4-マスタ!$C$3),""),IF(E21<マスタ!$C$2,F21-E21-G21,""))) -> 0.32291667 | J21: =IF(D21="休日","",IF(K21="",H21-I21,IF(H21=K21,"",H21-I21-K21))) -> 0 | K21: =IF(D21="休日","",IF(OR(E21="",F21=""),"",IF(F21>$X$13,IF(F21>$Z$13,$Z$13-$X$13,F21-$X$13),""))) | L21: =IF(D21="休日",H21,"")
B22: =B21+1 -> 45205 | C22: =B22 -> 45205 | D22: =IF(U22="稼働","稼働",IF(OR(WEEKDAY(B22)=1,WEEKDAY(B22)=7,C22="日",U22="祝日",U22="特休",U22="代休",U22="休み"),"休日",IF(C22="","","稼働"))) -> 稼働 | E22: 0.54166667 | F22: 0.72916667 | G22: =IF(AND(E22<>"",F22<>""),IF((F22-E22-マスタ!$B$7)>マスタ!$C$7,マスタ!$B$7,IF((F22-E22-マスタ!$B$6)>マスタ!$C$6,マスタ!$B$6,マスタ!$B$5)),"") -> 0 | H22: =IF(G22="","",F22-E22-G22) -> 0.1875 | I22: =IF(D22="休日","",IF(F22>マスタ!$C$2,IF(E22<マスタ!$C$2,マスタ!$C$2-E22-(マスタ!$C$4-マスタ!$C$3),""),IF(E22<マスタ!$C$2,F22-E22-G22,""))) -> 0.1875 | J22: =IF(D22="休日","",IF(K22="",H22-I22,IF(H22=K22,"",H22-I22-K22))) -> 0 | K22: =IF(D22="休日","",IF(OR(E22="",F22=""),"",IF(F22>$X$13,IF(F22>$Z$13,$Z$13-$X$13,F22-$X$13),""))) | L22: =IF(D22="休日",H22,"") | M22: 例）午前半休の場合
B23: =B22+1 -> 45206 | C23: =B23 -> 45206 | D23: =IF(U23="稼働","稼働",IF(OR(WEEKDAY(B23)=1,WEEKDAY(B23)=7,C23="日",U23="祝日",U23="特休",U23="代休",U23="休み"),"休日",IF(C23="","","稼働"))) -> 休日 | E23: 0.375 | F23: 0.72916667 | G23: =IF(AND(E23<>"",F23<>""),IF((F23-E23-マスタ!$B$7)>マスタ!$C$7,マスタ!$B$7,IF((F23-E23-マスタ!$B$6)>マスタ!$C$6,マスタ!$B$6,マスタ!$B$5)),"") -> 0.03125 | H23: =IF(G23="","",F23-E23-G23) -> 0.32291667 | I23: =IF(D23="休日","",IF(F23>マスタ!$C$2,IF(E23<マスタ!$C$2,マスタ!$C$2-E23-(マスタ!$C$4-マスタ!$C$3),""),IF(E23<マスタ!$C$2,F23-E23-G23,""))) | J23: =IF(D23="休日","",IF(K23="",H23-I23,IF(H23=K23,"",H23-I23-K23))) | K23: =IF(D23="休日","",IF(OR(E23="",F23=""),"",IF(F23>$X$13,IF(F23>$Z$13,$Z$13-$X$13,F23-$X$13),""))) | L23: =IF(D23="休日",H23,"") -> 0.32291667 | M23: 例）休日出勤の場合
B24: =B23+1 -> 45207 | C24: =B24 -> 45207 | D24: =IF(U24="稼働","稼働",IF(OR(WEEKDAY(B24)=1,WEEKDAY(B24)=7,C24="日",U24="祝日",U24="特休",U24="代休",U24="休み"),"休日",IF(C24="","","稼働"))) -> 休日 | E24: 0.375 | F24: 0.95833333 | G24: =IF(AND(E24<>"",F24<>""),IF((F24-E24-マスタ!$B$7)>マスタ!$C$7,マスタ!$B$7,IF((F24-E24-マスタ!$B$6)>マスタ!$C$6,マスタ!$B$6,マスタ!$B$5)),"") -> 0.041666667 | H24: =IF(G24="","",F24-E24-G24) -> 0.54166667 | I24: =IF(D24="休日","",IF(F24>マスタ!$C$2,IF(E24<マスタ!$C$2,マスタ!$C$2-E24-(マスタ!$C$4-マスタ!$C$3),""),IF(E24<マスタ!$C$2,F24-E24-G24,""))) | J24: =IF(D24="休日","",IF(K24="",H24-I24,IF(H24=K24,"",H24-I24-K24))) | K24: =IF(D24="休日","",IF(OR(E24="",F24=""),"",IF(F24>$X$13,IF(F24>$Z$13,$Z$13-$X$13,F24-$X$13),""))) | L24: =IF(D24="休日",H24,"") -> 0.54166667 | M24: 「PLの指示によりXXXXシステム変更作業のため休日出勤」のように コメント記載する
A25: =IF(DAY(B25)=1,B25,"") | B25: =B24+1 -> 45208 | C25: =B25 -> 45208 | D25: =IF(U25="稼働","稼働",IF(OR(WEEKDAY(B25)=1,WEEKDAY(B25)=7,C25="日",U25="祝日",U25="特休",U25="代休",U25="休み"),"休日",IF(C25="","","稼働"))) -> 休日 | G25: =IF(AND(E25<>"",F25<>""),IF((F25-E25-マスタ!$B$7)>マスタ!$C$7,マスタ!$B$7,IF((F25-E25-マスタ!$B$6)>マスタ!$C$6,マスタ!$B$6,マスタ!$B$5)),"") | H25: =IF(G25="","",F25-E25-G25) | I25: =IF(D25="休日","",IF(F25>マスタ!$C$2,IF(E25<マスタ!$C$2,マスタ!$C$2-E25-(マスタ!$C$4-マスタ!$C$3),""),IF(E25<マスタ!$C$2,F25-E25-G25,""))) | J25: =IF(D25="休日","",IF(K25="",H25-I25,IF(H25=K25,"",H25-I25-K25))) | K25: =IF(D25="休日","",IF(OR(E25="",F25=""),"",IF(F25>$X$13,IF(F25>$Z$13,$Z$13-$X$13,F25-$X$13),""))) | L25: =IF(D25="休日",H25,"") | M25: 例）祝日の場合、U列に「祝日」と入力 | U25: 祝日
A26: =IF(DAY(B26)=1,B26,"") | B26: =B25+1 -> 45209 | C26: =B26 -> 45209 | D26: =IF(U26="稼働","稼働",IF(OR(WEEKDAY(B26)=1,WEEKDAY(B26)=7,C26="日",U26="祝日",U26="特休",U26="代休",U26="休み"),"休日",IF(C26="","","稼働"))) -> 稼働 | E26: 0.375 | F26: 0.5 | G26: =IF(AND(E26<>"",F26<>""),IF((F26-E26-マスタ!$B$7)>マスタ!$C$7,マスタ!$B$7,IF((F26-E26-マスタ!$B$6)>マスタ!$C$6,マスタ!$B$6,マスタ!$B$5)),"") -> 0 | H26: =IF(G26="","",F26-E26-G26) -> 0.125 | I26: =IF(D26="休日","",IF(F26>マスタ!$C$2,IF(E26<マスタ!$C$2,マスタ!$C$2-E26-(マスタ!$C$4-マスタ!$C$3),""),IF(E26<マスタ!$C$2,F26-E26-G26,""))) -> 0.125 | J26: =IF(D26="休日","",IF(K26="",H26-I26,IF(H26=K26,"",H26-I26-K26))) -> 0 | K26: =IF(D26="休日","",IF(OR(E26="",F26=""),"",IF(F26>$X$13,IF(F26>$Z$13,$Z$13-$X$13,F26-$X$13),""))) | L26: =IF(D26="休日",H26,"") | M26: 例）午後半休の場合
A27: =IF(DAY(B27)=1,B27,"") | B27: =B26+1 -> 45210 | C27: =B27 -> 45210 | D27: =IF(U27="稼働","稼働",IF(OR(WEEKDAY(B27)=1,WEEKDAY(B27)=7,C27="日",U27="祝日",U27="特休",U27="代休",U27="休み"),"休日",IF(C27="","","稼働"))) -> 稼働 | E27: 0.91666667 | F27: 0.95833333 | G27: =IF(AND(E27<>"",F27<>""),IF((F27-E27-マスタ!$B$7)>マスタ!$C$7,マスタ!$B$7,IF((F27-E27-マスタ!$B$6)>マスタ!$C$6,マスタ!$B$6,マスタ!$B$5)),"") -> 0 | H27: =IF(G27="","",F27-E27-G27) -> 0.041666667 | I27: =IF(D27="休日","",IF(F27>マスタ!$C$2,IF(E27<マスタ!$C$2,マスタ!$C$2-E27-(マスタ!$C$4-マスタ!$C$3),""),IF(E27<マスタ!$C$2,F27-E27-G27,""))) | J27: =IF(D27="休日","",IF(K27="",H27-I27,IF(H27=K27,"",H27-I27-K27))) | K27: =IF(D27="休日","",IF(OR(E27="",F27=""),"",IF(F27>$X$13,IF(F27>$Z$13,$Z$13-$X$13,F27-$X$13),""))) -> 0.041666667 | L27: =IF(D27="休日",H27,"") | M27: 例）休暇日だったが、22:00～23:00の深夜対応をした場合
A28: =IF(DAY(B28)=1,B28,"") | B28: =B27+1 -> 45211 | C28: =B28 -> 45211 | D28: =IF(U28="稼働","稼働",IF(OR(WEEKDAY(B28)=1,WEEKDAY(B28)=7,C28="日",U28="祝日",U28="特休",U28="代休",U28="休み"),"休日",IF(C28="","","稼働"))) -> 稼働 | E28: 0.375 | F28: 0.83333333 | G28: =IF(AND(E28<>"",F28<>""),IF((F28-E28-マスタ!$B$7)>マスタ!$C$7,マスタ!$B$7,IF((F28-E28-マスタ!$B$6)>マスタ!$C$6,マスタ!$B$6,マスタ!$B$5)),"") -> 0.041666667 | H28: =IF(G28="","",F28-E28-G28) -> 0.41666667 | I28: =IF(D28="休日","",IF(F28>マスタ!$C$2,IF(E28<マスタ!$C$2,マスタ!$C$2-E28-(マスタ!$C$4-マスタ!$C$3),""),IF(E28<マスタ!$C$2,F28-E28-G28,""))) -> 0.33333333 | J28: =IF(D28="休日","",IF(K28="",H28-I28,IF(H28=K28,"",H28-I28-K28))) -> 0.083333333 | K28: =IF(D28="休日","",IF(OR(E28="",F28=""),"",IF(F28>$X$13,IF(F28>$Z$13,$Z$13-$X$13,F28-$X$13),""))) | L28: =IF(D28="休日",H28,"")
B29: =B28+1 -> 45212 | C29: =B29 -> 45212 | D29: =IF(U29="稼働","稼働",IF(OR(WEEKDAY(B29)=1,WEEKDAY(B29)=7,C29="日",U29="祝日",U29="特休",U29="代休",U29="休み"),"休日",IF(C29="","","稼働"))) -> 稼働 | E29: 0.375 | F29: 0.72916667 | G29: =IF(AND(E29<>"",F29<>""),IF((F29-E29-マスタ!$B$7)>マスタ!$C$7,マスタ!$B$7,IF((F29-E29-マスタ!$B$6)>マスタ!$C$6,マスタ!$B$6,マスタ!$B$5)),"") -> 0.03125 | H29: =IF(G29="","",F29-E29-G29) -> 0.32291667 | I29: =IF(D29="休日","",IF(F29>マスタ!$C$2,IF(E29<マスタ!$C$2,マスタ!$C$2-E29-(マスタ!$C$4-マスタ!$C$3),""),IF(E29<マスタ!$C$2,F29-E29-G29,""))) -> 0.32291667 | J29: =IF(D29="休日","",IF(K29="",H29-I29,IF(H29=K29,"",H29-I29-K29))) -> 0 | K29: =IF(D29="休日","",IF(OR(E29="",F29=""),"",IF(F29>$X$13,IF(F29>$Z$13,$Z$13-$X$13,F29-$X$13),""))) | L29: =IF(D29="休日",H29,"")
B30: =B29+1 -> 45213 | C30: =B30 -> 45213 | D30: =IF(U30="稼働","稼働",IF(OR(WEEKDAY(B30)=1,WEEKDAY(B30)=7,C30="日",U30="祝日",U30="特休",U30="代休",U30="休み"),"休日",IF(C30="","","稼働"))) -> 休日 | G30: =IF(AND(E30<>"",F30<>""),IF((F30-E30-マスタ!$B$7)>マスタ!$C$7,マスタ!$B$7,IF((F30-E30-マスタ!$B$6)>マスタ!$C$6,マスタ!$B$6,マスタ!$B$5)),"") | H30: =IF(G30="","",F30-E30-G30) | I30: =IF(D30="休日","",IF(F30>マスタ!$C$2,IF(E30<マスタ!$C$2,マスタ!$C$2-E30-(マスタ!$C$4-マスタ!$C$3),""),IF(E30<マスタ!$C$2,F30-E30-G30,""))) | J30: =IF(D30="休日","",IF(K30="",H30-I30,IF(H30=K30,"",H30-I30-K30))) | K30: =IF(D30="休日","",IF(OR(E30="",F30=""),"",IF(F30>$X$13,IF(F30>$Z$13,$Z$13-$X$13,F30-$X$13),""))) | L30: =IF(D30="休日",H30,"")
B31: =B30+1 -> 45214 | C31: =B31 -> 45214 | D31: =IF(U31="稼働","稼働",IF(OR(WEEKDAY(B31)=1,WEEKDAY(B31)=7,C31="日",U31="祝日",U31="特休",U31="代休",U31="休み"),"休日",IF(C31="","","稼働"))) -> 休日 | G31: =IF(AND(E31<>"",F31<>""),IF((F31-E31-マスタ!$B$7)>マスタ!$C$7,マスタ!$B$7,IF((F31-E31-マスタ!$B$6)>マスタ!$C$6,マスタ!$B$6,マスタ!$B$5)),"") | H31: =IF(G31="","",F31-E31-G31) | I31: =IF(D31="休日","",IF(F31>マスタ!$C$2,IF(E31<マスタ!$C$2,マスタ!$C$2-E31-(マスタ!$C$4-マスタ!$C$3),""),IF(E31<マスタ!$C$2,F31-E31-G31,""))) | J31: =IF(D31="休日","",IF(K31="",H31-I31,IF(H31=K31,"",H31-I31-K31))) | K31: =IF(D31="休日","",IF(OR(E31="",F31=""),"",IF(F31>$X$13,IF(F31>$Z$13,$Z$13-$X$13,F31-$X$13),""))) | L31: =IF(D31="休日",H31,"")
B32: =B31+1 -> 45215 | C32: =B32 -> 45215 | D32: =IF(U32="稼働","稼働",IF(OR(WEEKDAY(B32)=1,WEEKDAY(B32)=7,C32="日",U32="祝日",U32="特休",U32="代休",U32="休み"),"休日",IF(C32="","","稼働"))) -> 稼働 | E32: 0.375 | F32: 0.97916667 | G32: =IF(AND(E32<>"",F32<>""),IF((F32-E32-マスタ!$B$7)>マスタ!$C$7,マスタ!$B$7,IF((F32-E32-マスタ!$B$6)>マスタ!$C$6,マスタ!$B$6,マスタ!$B$5)),"") -> 0.041666667 | H32: 0.38541667 | I32: =IF(D32="休日","",IF(F32>マスタ!$C$2,IF(E32<マスタ!$C$2,マスタ!$C$2-E32-(マスタ!$C$4-マスタ!$C$3),""),IF(E32<マスタ!$C$2,F32-E32-G32,""))) -> 0.33333333 | J32: =IF(D32="休日","",IF(K32="",H32-I32,IF(H32=K32,"",H32-I32-K32))) -> 0.010416667 | K32: 0.041666667 | L32: =IF(D32="休日",H32,"") | M32: 例）退勤後に22:30〜23:30の１時間、深夜対応をしたケース。 F列に最終時間、H列にその日の合計作業時間を手入力して下さい。 K列の深夜時間を手入力してください。
B33: =B32+1 -> 45216 | C33: =B33 -> 45216 | D33: =IF(U33="稼働","稼働",IF(OR(WEEKDAY(B33)=1,WEEKDAY(B33)=7,C33="日",U33="祝日",U33="特休",U33="代休",U33="休み"),"休日",IF(C33="","","稼働"))) -> 稼働 | E33: 0.375 | F33: 0.91666667 | G33: =IF(AND(E33<>"",F33<>""),IF((F33-E33-マスタ!$B$7)>マスタ!$C$7,マスタ!$B$7,IF((F33-E33-マスタ!$B$6)>マスタ!$C$6,マスタ!$B$6,マスタ!$B$5)),"") -> 0.041666667 | H33: 0.36458333 | I33: =IF(D33="休日","",IF(F33>マスタ!$C$2,IF(E33<マスタ!$C$2,マスタ!$C$2-E33-(マスタ!$C$4-マスタ!$C$3),""),IF(E33<マスタ!$C$2,F33-E33-G33,""))) -> 0.33333333 | J33: =IF(D33="休日","",IF(K33="",H33-I33,IF(H33=K33,"",H33-I33-K33))) -> 0.03125 | K33: =IF(D33="休日","",IF(OR(E33="",F33=""),"",IF(F33>$X$13,IF(F33>$Z$13,$Z$13-$X$13,F33-$X$13),""))) | L33: =IF(D33="休日",H33,"") | M33: 例）退勤後に21:00〜22:00の１時間の追加作業をしたケース。 F列に最終時間、H列にその日の合計作業時間を手入力して下さい。
B34: =B33+1 -> 45217 | C34: =B34 -> 45217 | D34: =IF(U34="稼働","稼働",IF(OR(WEEKDAY(B34)=1,WEEKDAY(B34)=7,C34="日",U34="祝日",U34="特休",U34="代休",U34="休み"),"休日",IF(C34="","","稼働"))) -> 稼働 | E34: 0.375 | F34: 0.72916667 | G34: =IF(AND(E34<>"",F34<>""),IF((F34-E34-マスタ!$B$7)>マスタ!$C$7,マスタ!$B$7,IF((F34-E34-マスタ!$B$6)>マスタ!$C$6,マスタ!$B$6,マスタ!$B$5)),"") -> 0.03125 | H34: =IF(G34="","",F34-E34-G34) -> 0.32291667 | I34: =IF(D34="休日","",IF(F34>マスタ!$C$2,IF(E34<マスタ!$C$2,マスタ!$C$2-E34-(マスタ!$C$4-マスタ!$C$3),""),IF(E34<マスタ!$C$2,F34-E34-G34,""))) -> 0.32291667 | J34: =IF(D34="休日","",IF(K34="",H34-I34,IF(H34=K34,"",H34-I34-K34))) -> 0 | K34: =IF(D34="休日","",IF(OR(E34="",F34=""),"",IF(F34>$X$13,IF(F34>$Z$13,$Z$13-$X$13,F34-$X$13),""))) | L34: =IF(D34="休日",H34,"")
B35: =B34+1 -> 45218 | C35: =B35 -> 45218 | D35: =IF(U35="稼働","稼働",IF(OR(WEEKDAY(B35)=1,WEEKDAY(B35)=7,C35="日",U35="祝日",U35="特休",U35="代休",U35="休み"),"休日",IF(C35="","","稼働"))) -> 休日 | G35: =IF(AND(E35<>"",F35<>""),IF((F35-E35-マスタ!$B$7)>マスタ!$C$7,マスタ!$B$7,IF((F35-E35-マスタ!$B$6)>マスタ!$C$6,マスタ!$B$6,マスタ!$B$5)),"") | H35: =IF(G35="","",F35-E35-G35) | I35: =IF(D35="休日","",IF(F35>マスタ!$C$2,IF(E35<マスタ!$C$2,マスタ!$C$2-E35-(マスタ!$C$4-マスタ!$C$3),""),IF(E35<マスタ!$C$2,F35-E35-G35,""))) | J35: =IF(D35="休日","",IF(K35="",H35-I35,IF(H35=K35,"",H35-I35-K35))) | K35: =IF(D35="休日","",IF(OR(E35="",F35=""),"",IF(F35>$X$13,IF(F35>$Z$13,$Z$13-$X$13,F35-$X$13),""))) | L35: =IF(D35="休日",H35,"") | M35: 例）年休、代休など休暇の場合、U列に「休み」と入力 | U35: 休み
B36: =B35+1 -> 45219 | C36: =B36 -> 45219 | D36: =IF(U36="稼働","稼働",IF(OR(WEEKDAY(B36)=1,WEEKDAY(B36)=7,C36="日",U36="祝日",U36="特休",U36="代休",U36="休み"),"休日",IF(C36="","","稼働"))) -> 稼働 | E36: 0.375 | F36: 0.72916667 | G36: =IF(AND(E36<>"",F36<>""),IF((F36-E36-マスタ!$B$7)>マスタ!$C$7,マスタ!$B$7,IF((F36-E36-マスタ!$B$6)>マスタ!$C$6,マスタ!$B$6,マスタ!$B$5)),"") -> 0.03125 | H36: =IF(G36="","",F36-E36-G36) -> 0.32291667 | I36: =IF(D36="休日","",IF(F36>マスタ!$C$2,IF(E36<マスタ!$C$2,マスタ!$C$2-E36-(マスタ!$C$4-マスタ!$C$3),""),IF(E36<マスタ!$C$2,F36-E36-G36,""))) -> 0.32291667 | J36: =IF(D36="休日","",IF(K36="",H36-I36,IF(H36=K36,"",H36-I36-K36))) -> 0 | K36: =IF(D36="休日","",IF(OR(E36="",F36=""),"",IF(F36>$X$13,IF(F36>$Z$13,$Z$13-$X$13,F36-$X$13),""))) | L36: =IF(D36="休日",H36,"")
B37: =B36+1 -> 45220 | C37: =B37 -> 45220 | D37: =IF(U37="稼働","稼働",IF(OR(WEEKDAY(B37)=1,WEEKDAY(B37)=7,C37="日",U37="祝日",U37="特休",U37="代休",U37="休み"),"休日",IF(C37="","","稼働"))) -> 休日 | G37: =IF(AND(E37<>"",F37<>""),IF((F37-E37-マスタ!$B$7)>マスタ!$C$7,マスタ!$B$7,IF((F37-E37-マスタ!$B$6)>マスタ!$C$6,マスタ!$B$6,マスタ!$B$5)),"") | H37: =IF(G37="","",F37-E37-G37) | I37: =IF(D37="休日","",IF(F37>マスタ!$C$2,IF(E37<マスタ!$C$2,マスタ!$C$2-E37-(マスタ!$C$4-マスタ!$C$3),""),IF(E37<マスタ!$C$2,F37-E37-G37,""))) | J37: =IF(D37="休日","",IF(K37="",H37-I37,IF(H37=K37,"",H37-I37-K37))) | K37: =IF(D37="休日","",IF(OR(E37="",F37=""),"",IF(F37>$X$13,IF(F37>$Z$13,$Z$13-$X$13,F37-$X$13),""))) | L37: =IF(D37="休日",H37,"")
B38: =B37+1 -> 45221 | C38: =B38 -> 45221 | D38: =IF(U38="稼働","稼働",IF(OR(WEEKDAY(B38)=1,WEEKDAY(B38)=7,C38="日",U38="祝日",U38="特休",U38="代休",U38="休み"),"休日",IF(C38="","","稼働"))) -> 休日 | G38: =IF(AND(E38<>"",F38<>""),IF((F38-E38-マスタ!$B$7)>マスタ!$C$7,マスタ!$B$7,IF((F38-E38-マスタ!$B$6)>マスタ!$C$6,マスタ!$B$6,マスタ!$B$5)),"") | H38: =IF(G38="","",F38-E38-G38) | I38: =IF(D38="休日","",IF(F38>マスタ!$C$2,IF(E38<マスタ!$C$2,マスタ!$C$2-E38-(マスタ!$C$4-マスタ!$C$3),""),IF(E38<マスタ!$C$2,F38-E38-G38,""))) | J38: =IF(D38="休日","",IF(K38="",H38-I38,IF(H38=K38,"",H38-I38-K38))) | K38: =IF(D38="休日","",IF(OR(E38="",F38=""),"",IF(F38>$X$13,IF(F38>$Z$13,$Z$13-$X$13,F38-$X$13),""))) | L38: =IF(D38="休日",H38,"")
B39: =B38+1 -> 45222 | C39: =B39 -> 45222 | D39: =IF(U39="稼働","稼働",IF(OR(WEEKDAY(B39)=1,WEEKDAY(B39)=7,C39="日",U39="祝日",U39="特休",U39="代休",U39="休み"),"休日",IF(C39="","","稼働"))) -> 稼働 | E39: 0.375 | F39: 0.72916667 | G39: =IF(AND(E39<>"",F39<>""),IF((F39-E39-マスタ!$B$7)>マスタ!$C$7,マスタ!$B$7,IF((F39-E39-マスタ!$B$6)>マスタ!$C$6,マスタ!$B$6,マスタ!$B$5)),"") -> 0.03125 | H39: =IF(G39="","",F39-E39-G39) -> 0.32291667 | I39: =IF(D39="休日","",IF(F39>マスタ!$C$2,IF(E39<マスタ!$C$2,マスタ!$C$2-E39-(マスタ!$C$4-マスタ!$C$3),""),IF(E39<マスタ!$C$2,F39-E39-G39,""))) -> 0.32291667 | J39: =IF(D39="休日","",IF(K39="",H39-I39,IF(H39=K39,"",H39-I39-K39))) -> 0 | K39: =IF(D39="休日","",IF(OR(E39="",F39=""),"",IF(F39>$X$13,IF(F39>$Z$13,$Z$13-$X$13,F39-$X$13),""))) | L39: =IF(D39="休日",H39,"")
B40: =B39+1 -> 45223 | C40: =B40 -> 45223 | D40: =IF(U40="稼働","稼働",IF(OR(WEEKDAY(B40)=1,WEEKDAY(B40)=7,C40="日",U40="祝日",U40="特休",U40="代休",U40="休み"),"休日",IF(C40="","","稼働"))) -> 稼働 | E40: 0.375 | F40: 0.72916667 | G40: =IF(AND(E40<>"",F40<>""),IF((F40-E40-マスタ!$B$7)>マスタ!$C$7,マスタ!$B$7,IF((F40-E40-マスタ!$B$6)>マスタ!$C$6,マスタ!$B$6,マスタ!$B$5)),"") -> 0.03125 | H40: =IF(G40="","",F40-E40-G40) -> 0.32291667 | I40: =IF(D40="休日","",IF(F40>マスタ!$C$2,IF(E40<マスタ!$C$2,マスタ!$C$2-E40-(マスタ!$C$4-マスタ!$C$3),""),IF(E40<マスタ!$C$2,F40-E40-G40,""))) -> 0.32291667 | J40: =IF(D40="休日","",IF(K40="",H40-I40,IF(H40=K40,"",H40-I40-K40))) -> 0 | K40: =IF(D40="休日","",IF(OR(E40="",F40=""),"",IF(F40>$X$13,IF(F40>$Z$13,$Z$13-$X$13,F40-$X$13),""))) | L40: =IF(D40="休日",H40,"")
B41: =B40+1 -> 45224 | C41: =B41 -> 45224 | D41: =IF(U41="稼働","稼働",IF(OR(WEEKDAY(B41)=1,WEEKDAY(B41)=7,C41="日",U41="祝日",U41="特休",U41="代休",U41="休み"),"休日",IF(C41="","","稼働"))) -> 稼働 | E41: 0.375 | F41: 0.72916667 | G41: =IF(AND(E41<>"",F41<>""),IF((F41-E41-マスタ!$B$7)>マスタ!$C$7,マスタ!$B$7,IF((F41-E41-マスタ!$B$6)>マスタ!$C$6,マスタ!$B$6,マスタ!$B$5)),"") -> 0.03125 | H41: =IF(G41="","",F41-E41-G41) -> 0.32291667 | I41: =IF(D41="休日","",IF(F41>マスタ!$C$2,IF(E41<マスタ!$C$2,マスタ!$C$2-E41-(マスタ!$C$4-マスタ!$C$3),""),IF(E41<マスタ!$C$2,F41-E41-G41,""))) -> 0.32291667 | J41: =IF(D41="休日","",IF(K41="",H41-I41,IF(H41=K41,"",H41-I41-K41))) -> 0 | K41: =IF(D41="休日","",IF(OR(E41="",F41=""),"",IF(F41>$X$13,IF(F41>$Z$13,$Z$13-$X$13,F41-$X$13),""))) | L41: =IF(D41="休日",H41,"")
B42: =B41+1 -> 45225 | C42: =B42 -> 45225 | D42: =IF(U42="稼働","稼働",IF(OR(WEEKDAY(B42)=1,WEEKDAY(B42)=7,C42="日",U42="祝日",U42="特休",U42="代休",U42="休み"),"休日",IF(C42="","","稼働"))) -> 稼働 | E42: 0.375 | F42: 0.72916667 | G42: =IF(AND(E42<>"",F42<>""),IF((F42-E42-マスタ!$B$7)>マスタ!$C$7,マスタ!$B$7,IF((F42-E42-マスタ!$B$6)>マスタ!$C$6,マスタ!$B$6,マスタ!$B$5)),"") -> 0.03125 | H42: =IF(G42="","",F42-E42-G42) -> 0.32291667 | I42: =IF(D42="休日","",IF(F42>マスタ!$C$2,IF(E42<マスタ!$C$2,マスタ!$C$2-E42-(マスタ!$C$4-マスタ!$C$3),""),IF(E42<マスタ!$C$2,F42-E42-G42,""))) -> 0.32291667 | J42: =IF(D42="休日","",IF(K42="",H42-I42,IF(H42=K42,"",H42-I42-K42))) -> 0 | K42: =IF(D42="休日","",IF(OR(E42="",F42=""),"",IF(F42>$X$13,IF(F42>$Z$13,$Z$13-$X$13,F42-$X$13),""))) | L42: =IF(D42="休日",H42,"")
B43: =B42+1 -> 45226 | C43: =B43 -> 45226 | D43: =IF(U43="稼働","稼働",IF(OR(WEEKDAY(B43)=1,WEEKDAY(B43)=7,C43="日",U43="祝日",U43="特休",U43="代休",U43="休み"),"休日",IF(C43="","","稼働"))) -> 稼働 | E43: 0.375 | F43: 0.72916667 | G43: =IF(AND(E43<>"",F43<>""),IF((F43-E43-マスタ!$B$7)>マスタ!$C$7,マスタ!$B$7,IF((F43-E43-マスタ!$B$6)>マスタ!$C$6,マスタ!$B$6,マスタ!$B$5)),"") -> 0.03125 | H43: =IF(G43="","",F43-E43-G43) -> 0.32291667 | I43: =IF(D43="休日","",IF(F43>マスタ!$C$2,IF(E43<マスタ!$C$2,マスタ!$C$2-E43-(マスタ!$C$4-マスタ!$C$3),""),IF(E43<マスタ!$C$2,F43-E43-G43,""))) -> 0.32291667 | J43: =IF(D43="休日","",IF(K43="",H43-I43,IF(H43=K43,"",H43-I43-K43))) -> 0 | K43: =IF(D43="休日","",IF(OR(E43="",F43=""),"",IF(F43>$X$13,IF(F43>$Z$13,$Z$13-$X$13,F43-$X$13),""))) | L43: =IF(D43="休日",H43,"")
...

Sheet 202111_記入要領
F1: 勤務実績表 兼 作業報告書 | N1: 注文番号：B540000
G2: 44501 | K2: 報告者 | M2: ZEXIS承認者1 | O2: ZEXIS承認者2
E3: =DATEVALUE(TEXT(G2,"yyyy/mm/") & "01") -> 44501 | H3: =EDATE(E3,1)-1 -> 44530
B4: 会社名： | D4: 株式会社●●●●●●●●●●
B5: 作業者： | D5: ●● ●● | H5: 合計時間 | I5: =SUM(H8:H38) -> 0.71875 | K5: yyyy/mm/dd | M5: yyyy/mm/dd | O5: yyyy/mm/dd
A7: 月 | B7: 日 | C7: 曜日 | D7: 勤務区分 | E7: 開 始 | F7: 終 了 | G7: 休憩時間 | H7: 勤務時間 | I7: 作業内容 | P7: 検印 | Q7: 休み
A8: =B8 -> 44501 | B8: =E3 -> 44501 | C8: =B8 -> 44501 | D8: =IF(Q8="勤務","勤務",IF(OR(WEEKDAY(B8)=1,WEEKDAY(B8)=7,C8="日",Q8="祝日",Q8="特休",Q8="代休",Q8="休み"),"休日",IF(C8="","","勤務"))) -> 勤務 | E8: 0.375 | F8: 0.8125 | G8: =IF(F8="","",IF(F8=":","",IF(F8>=VALUE("13:15"),IF(F8>VALUE("17:45"),IF(F8>VALUE("21:00"),"1:15","1:00"),"0:45"),0))) -> 1:00 | H8: =IF(G8="","",F8-E8-G8) -> 0.39583333 | I8: 【在宅勤務】a-MRO運用、Unicorn運用・ツール支援
B9: =B8+1 -> 44502 | C9: =B9 -> 44502 | D9: =IF(Q9="勤務","勤務",IF(OR(WEEKDAY(B9)=1,WEEKDAY(B9)=7,C9="日",Q9="祝日",Q9="特休",Q9="代休",Q9="休み"),"休日",IF(C9="","","勤務"))) -> 勤務 | E9: 0.375 | F9: 0.72916667 | G9: =IF(F9="","",IF(F9=":","",IF(F9>=VALUE("13:15"),IF(F9>VALUE("17:45"),IF(F9>VALUE("21:00"),"1:15","1:00"),"0:45"),0))) -> 0:45 | H9: =IF(G9="","",F9-E9-G9) -> 0.32291667 | I9: a-MRO運用、Unicorn運用・ツール支援 | S9: 必須入力項目
B10: =B9+1 -> 44503 | C10: =B10 -> 44503 | D10: =IF(Q10="勤務","勤務",IF(OR(WEEKDAY(B10)=1,WEEKDAY(B10)=7,C10="日",Q10="祝日",Q10="特休",Q10="代休",Q10="休み"),"休日",IF(C10="","","勤務"))) -> 勤務 | G10: =IF(F10="","",IF(F10=":","",IF(F10>=VALUE("13:15"),IF(F10>VALUE("17:45"),IF(F10>VALUE("21:00"),"1:15","1:00"),"0:45"),0))) | H10: =IF(G10="","",F10-E10-G10) | S10: 入力不可項目
B11: =B10+1 -> 44504 | C11: =B11 -> 44504 | D11: =IF(Q11="勤務","勤務",IF(OR(WEEKDAY(B11)=1,WEEKDAY(B11)=7,C11="日",Q11="祝日",Q11="特休",Q11="代休",Q11="休み"),"休日",IF(C11="","","勤務"))) -> 勤務 | G11: =IF(F11="","",IF(F11=":","",IF(F11>=VALUE("13:15"),IF(F11>VALUE("17:45"),IF(F11>VALUE("21:00"),"1:15","1:00"),"0:45"),0))) | H11: =IF(G11="","",F11-E11-G11) | S11: その他項目はフリー
B12: =B11+1 -> 44505 | C12: =B12 -> 44505 | D12: =IF(Q12="勤務","勤務",IF(OR(WEEKDAY(B12)=1,WEEKDAY(B12)=7,C12="日",Q12="祝日",Q12="特休",Q12="代休",Q12="休み"),"休日",IF(C12="","","勤務"))) -> 勤務 | G12: =IF(F12="","",IF(F12=":","",IF(F12>=VALUE("13:15"),IF(F12>VALUE("17:45"),IF(F12>VALUE("21:00"),"1:15","1:00"),"0:45"),0))) | H12: =IF(G12="","",F12-E12-G12)
B13: =B12+1 -> 44506 | C13: =B13 -> 44506 | D13: =IF(Q13="勤務","勤務",IF(OR(WEEKDAY(B13)=1,WEEKDAY(B13)=7,C13="日",Q13="祝日",Q13="特休",Q13="代休",Q13="休み"),"休日",IF(C13="","","勤務"))) -> 休日 | G13: =IF(F13="","",IF(F13=":","",IF(F13>=VALUE("13:15"),IF(F13>VALUE("17:45"),IF(F13>VALUE("21:00"),"1:15","1:00"),"0:45"),0))) | H13: =IF(G13="","",F13-E13-G13)
B14: =B13+1 -> 44507 | C14: =B14 -> 44507 | D14: =IF(Q14="勤務","勤務",IF(OR(WEEKDAY(B14)=1,WEEKDAY(B14)=7,C14="日",Q14="祝日",Q14="特休",Q14="代休",Q14="休み"),"休日",IF(C14="","","勤務"))) -> 休日 | G14: =IF(F14="","",IF(F14=":","",IF(F14>=VALUE("13:15"),IF(F14>VALUE("17:45"),IF(F14>VALUE("21:00"),"1:15","1:00"),"0:45"),0))) | H14: =IF(G14="","",F14-E14-G14)
B15: =B14+1 -> 44508 | C15: =B15 -> 44508 | D15: =IF(Q15="勤務","勤務",IF(OR(WEEKDAY(B15)=1,WEEKDAY(B15)=7,C15="日",Q15="祝日",Q15="特休",Q15="代休",Q15="休み"),"休日",IF(C15="","","勤務"))) -> 勤務 | G15: =IF(F15="","",IF(F15=":","",IF(F15>=VALUE("13:15"),IF(F15>VALUE("17:45"),IF(F15>VALUE("21:00"),"1:15","1:00"),"0:45"),0))) | H15: =IF(G15="","",F15-E15-G15)
A16: =IF(DAY(B16)=1,B16,"") | B16: =B15+1 -> 44509 | C16: =B16 -> 44509 | D16: =IF(Q16="勤務","勤務",IF(OR(WEEKDAY(B16)=1,WEEKDAY(B16)=7,C16="日",Q16="祝日",Q16="特休",Q16="代休",Q16="休み"),"休日",IF(C16="","","勤務"))) -> 勤務 | G16: =IF(F16="","",IF(F16=":","",IF(F16>=VALUE("13:15"),IF(F16>VALUE("17:45"),IF(F16>VALUE("21:00"),"1:15","1:00"),"0:45"),0))) | H16: =IF(G16="","",F16-E16-G16)
A17: =IF(DAY(B17)=1,B17,"") | B17: =B16+1 -> 44510 | C17: =B17 -> 44510 | D17: =IF(Q17="勤務","勤務",IF(OR(WEEKDAY(B17)=1,WEEKDAY(B17)=7,C17="日",Q17="祝日",Q17="特休",Q17="代休",Q17="休み"),"休日",IF(C17="","","勤務"))) -> 勤務 | G17: =IF(F17="","",IF(F17=":","",IF(F17>=VALUE("13:15"),IF(F17>VALUE("17:45"),IF(F17>VALUE("21:00"),"1:15","1:00"),"0:45"),0))) | H17: =IF(G17="","",F17-E17-G17)
A18: =IF(DAY(B18)=1,B18,"") | B18: =B17+1 -> 44511 | C18: =B18 -> 44511 | D18: =IF(Q18="勤務","勤務",IF(OR(WEEKDAY(B18)=1,WEEKDAY(B18)=7,C18="日",Q18="祝日",Q18="特休",Q18="代休",Q18="休み"),"休日",IF(C18="","","勤務"))) -> 勤務 | G18: =IF(F18="","",IF(F18=":","",IF(F18>=VALUE("13:15"),IF(F18>VALUE("17:45"),IF(F18>VALUE("21:00"),"1:15","1:00"),"0:45"),0))) | H18: =IF(G18="","",F18-E18-G18)
A19: =IF(DAY(B19)=1,B19,"") | B19: =B18+1 -> 44512 | C19: =B19 -> 44512 | D19: =IF(Q19="勤務","勤務",IF(OR(WEEKDAY(B19)=1,WEEKDAY(B19)=7,C19="日",Q19="祝日",Q19="特休",Q19="代休",Q19="休み"),"休日",IF(C19="","","勤務"))) -> 勤務 | G19: =IF(F19="","",IF(F19=":","",IF(F19>=VALUE("13:15"),IF(F19>VALUE("17:45"),IF(F19>VALUE("21:00"),"1:15","1:00"),"0:45"),0))) | H19: =IF(G19="","",F19-E19-G19)
B20: =B19+1 -> 44513 | C20: =B20 -> 44513 | D20: =IF(Q20="勤務","勤務",IF(OR(WEEKDAY(B20)=1,WEEKDAY(B20)=7,C20="日",Q20="祝日",Q20="特休",Q20="代休",Q20="休み"),"休日",IF(C20="","","勤務"))) -> 休日 | G20: =IF(F20="","",IF(F20=":","",IF(F20>=VALUE("13:15"),IF(F20>VALUE("17:45"),IF(F20>VALUE("21:00"),"1:15","1:00"),"0:45"),0))) | H20: =IF(G20="","",F20-E20-G20)
B21: =B20+1 -> 44514 | C21: =B21 -> 44514 | D21: =IF(Q21="勤務","勤務",IF(OR(WEEKDAY(B21)=1,WEEKDAY(B21)=7,C21="日",Q21="祝日",Q21="特休",Q21="代休",Q21="休み"),"休日",IF(C21="","","勤務"))) -> 休日 | G21: =IF(F21="","",IF(F21=":","",IF(F21>=VALUE("13:15"),IF(F21>VALUE("17:45"),IF(F21>VALUE("21:00"),"1:15","1:00"),"0:45"),0))) | H21: =IF(G21="","",F21-E21-G21)
B22: =B21+1 -> 44515 | C22: =B22 -> 44515 | D22: =IF(Q22="勤務","勤務",IF(OR(WEEKDAY(B22)=1,WEEKDAY(B22)=7,C22="日",Q22="祝日",Q22="特休",Q22="代休",Q22="休み"),"休日",IF(C22="","","勤務"))) -> 勤務 | G22: =IF(F22="","",IF(F22=":","",IF(F22>=VALUE("13:15"),IF(F22>VALUE("17:45"),IF(F22>VALUE("21:00"),"1:15","1:00"),"0:45"),0))) | H22: =IF(G22="","",F22-E22-G22)
B23: =B22+1 -> 44516 | C23: =B23 -> 44516 | D23: =IF(Q23="勤務","勤務",IF(OR(WEEKDAY(B23)=1,WEEKDAY(B23)=7,C23="日",Q23="祝日",Q23="特休",Q23="代休",Q23="休み"),"休日",IF(C23="","","勤務"))) -> 勤務 | G23: =IF(F23="","",IF(F23=":","",IF(F23>=VALUE("13:15"),IF(F23>VALUE("17:45"),IF(F23>VALUE("21:00"),"1:15","1:00"),"0:45"),0))) | H23: =IF(G23="","",F23-E23-G23)
B24: =B23+1 -> 44517 | C24: =B24 -> 44517 | D24: =IF(Q24="勤務","勤務",IF(OR(WEEKDAY(B24)=1,WEEKDAY(B24)=7,C24="日",Q24="祝日",Q24="特休",Q24="代休",Q24="休み"),"休日",IF(C24="","","勤務"))) -> 勤務 | G24: =IF(F24="","",IF(F24=":","",IF(F24>=VALUE("13:15"),IF(F24>VALUE("17:45"),IF(F24>VALUE("21:00"),"1:15","1:00"),"0:45"),0))) | H24: =IF(G24="","",F24-E24-G24)
B25: =B24+1 -> 44518 | C25: =B25 -> 44518 | D25: =IF(Q25="勤務","勤務",IF(OR(WEEKDAY(B25)=1,WEEKDAY(B25)=7,C25="日",Q25="祝日",Q25="特休",Q25="代休",Q25="休み"),"休日",IF(C25="","","勤務"))) -> 勤務 | G25: =IF(F25="","",IF(F25=":","",IF(F25>=VALUE("13:15"),IF(F25>VALUE("17:45"),IF(F25>VALUE("21:00"),"1:15","1:00"),"0:45"),0))) | H25: =IF(G25="","",F25-E25-G25)
B26: =B25+1 -> 44519 | C26: =B26 -> 44519 | D26: =IF(Q26="勤務","勤務",IF(OR(WEEKDAY(B26)=1,WEEKDAY(B26)=7,C26="日",Q26="祝日",Q26="特休",Q26="代休",Q26="休み"),"休日",IF(C26="","","勤務"))) -> 勤務 | G26: =IF(F26="","",IF(F26=":","",IF(F26>=VALUE("13:15"),IF(F26>VALUE("17:45"),IF(F26>VALUE("21:00"),"1:15","1:00"),"0:45"),0))) | H26: =IF(G26="","",F26-E26-G26)
B27: =B26+1 -> 44520 | C27: =B27 -> 44520 | D27: =IF(Q27="勤務","勤務",IF(OR(WEEKDAY(B27)=1,WEEKDAY(B27)=7,C27="日",Q27="祝日",Q27="特休",Q27="代休",Q27="休み"),"休日",IF(C27="","","勤務"))) -> 休日 | G27: =IF(F27="","",IF(F27=":","",IF(F27>=VALUE("13:15"),IF(F27>VALUE("17:45"),IF(F27>VALUE("21:00"),"1:15","1:00"),"0:45"),0))) | H27: =IF(G27="","",F27-E27-G27)
B28: =B27+1 -> 44521 | C28: =B28 -> 44521 | D28: =IF(Q28="勤務","勤務",IF(OR(WEEKDAY(B28)=1,WEEKDAY(B28)=7,C28="日",Q28="祝日",Q28="特休",Q28="代休",Q28="休み"),"休日",IF(C28="","","勤務"))) -> 休日 | G28: =IF(F28="","",IF(F28=":","",IF(F28>=VALUE("13:15"),IF(F28>VALUE("17:45"),IF(F28>VALUE("21:00"),"1:15","1:00"),"0:45"),0))) | H28: =IF(G28="","",F28-E28-G28)
B29: =B28+1 -> 44522 | C29: =B29 -> 44522 | D29: =IF(Q29="勤務","勤務",IF(OR(WEEKDAY(B29)=1,WEEKDAY(B29)=7,C29="日",Q29="祝日",Q29="特休",Q29="代休",Q29="休み"),"休日",IF(C29="","","勤務"))) -> 休日 | G29: =IF(F29="","",IF(F29=":","",IF(F29>=VALUE("13:15"),IF(F29>VALUE("17:45"),IF(F29>VALUE("21:00"),"1:15","1:00"),"0:45"),0))) | H29: =IF(G29="","",F29-E29-G29) | Q29: 休み
B30: =B29+1 -> 44523 | C30: =B30 -> 44523 | D30: =IF(Q30="勤務","勤務",IF(OR(WEEKDAY(B30)=1,WEEKDAY(B30)=7,C30="日",Q30="祝日",Q30="特休",Q30="代休",Q30="休み"),"休日",IF(C30="","","勤務"))) -> 休日 | G30: =IF(F30="","",IF(F30=":","",IF(F30>=VALUE("13:15"),IF(F30>VALUE("17:45"),IF(F30>VALUE("21:00"),"1:15","1:00"),"0:45"),0))) | H30: =IF(G30="","",F30-E30-G30) | Q30: 祝日
B31: =B30+1 -> 44524 | C31: =B31 -> 44524 | D31: =IF(Q31="勤務","勤務",IF(OR(WEEKDAY(B31)=1,WEEKDAY(B31)=7,C31="日",Q31="祝日",Q31="特休",Q31="代休",Q31="休み"),"休日",IF(C31="","","勤務"))) -> 勤務 | G31: =IF(F31="","",IF(F31=":","",IF(F31>=VALUE("13:15"),IF(F31>VALUE("17:45"),IF(F31>VALUE("21:00"),"1:15","1:00"),"0:45"),0))) | H31: =IF(G31="","",F31-E31-G31)
B32: =B31+1 -> 44525 | C32: =B32 -> 44525 | D32: =IF(Q32="勤務","勤務",IF(OR(WEEKDAY(B32)=1,WEEKDAY(B32)=7,C32="日",Q32="祝日",Q32="特休",Q32="代休",Q32="休み"),"休日",IF(C32="","","勤務"))) -> 勤務 | G32: =IF(F32="","",IF(F32=":","",IF(F32>=VALUE("13:15"),IF(F32>VALUE("17:45"),IF(F32>VALUE("21:00"),"1:15","1:00"),"0:45"),0))) | H32: =IF(G32="","",F32-E32-G32)
B33: =B32+1 -> 44526 | C33: =B33 -> 44526 | D33: =IF(Q33="勤務","勤務",IF(OR(WEEKDAY(B33)=1,WEEKDAY(B33)=7,C33="日",Q33="祝日",Q33="特休",Q33="代休",Q33="休み"),"休日",IF(C33="","","勤務"))) -> 勤務 | G33: =IF(F33="","",IF(F33=":","",IF(F33>=VALUE("13:15"),IF(F33>VALUE("17:45"),IF(F33>VALUE("21:00"),"1:15","1:00"),"0:45"),0))) | H33: =IF(G33="","",F33-E33-G33)
B34: =B33+1 -> 44527 | C34: =B34 -> 44527 | D34: =IF(Q34="勤務","勤務",IF(OR(WEEKDAY(B34)=1,WEEKDAY(B34)=7,C34="日",Q34="祝日",Q34="特休",Q34="代休",Q34="休み"),"休日",IF(C34="","","勤務"))) -> 休日 | G34: =IF(F34="","",IF(F34=":","",IF(F34>=VALUE("13:15"),IF(F34>VALUE("17:45"),IF(F34>VALUE("21:00"),"1:15","1:00"),"0:45"),0))) | H34: =IF(G34="","",F34-E34-G34)
B35: =B34+1 -> 44528 | C35: =B35 -> 44528 | D35: =IF(Q35="勤務","勤務",IF(OR(WEEKDAY(B35)=1,WEEKDAY(B35)=7,C35="日",Q35="祝日",Q35="特休",Q35="代休",Q35="休み"),"休日",IF(C35="","","勤務"))) -> 休日 | G35: =IF(F35="","",IF(F35=":","",IF(F35>=VALUE("13:15"),IF(F35>VALUE("17:45"),IF(F35>VALUE("21:00"),"1:15","1:00"),"0:45"),0))) | H35: =IF(G35="","",F35-E35-G35)
B36: =IF(DAY(B35+1) < 5,"",B35+1) -> 44529 | C36: =B36 -> 44529 | D36: =IF(B36="","",IF(Q36="勤務","勤務",IF(OR(WEEKDAY(B36)=1,WEEKDAY(B36)=7,C36="日",Q36="祝日",Q36="特休",Q36="代休",Q36="休み"),"休日",IF(C36="","","勤務")))) -> 勤務 | G36: =IF(F36="","",IF(F36=":","",IF(F36>=VALUE("13:15"),IF(F36>VALUE("17:45"),IF(F36>VALUE("21:00"),"1:15","1:00"),"0:45"),0))) | H36: =IF(G36="","",F36-E36-G36)
B37: =IF(B36="","",IF(DAY(B36+1) < 5,"",B36+1)) -> 44530 | C37: =B37 -> 44530 | D37: =IF(B37="","",IF(Q37="勤務","勤務",IF(OR(WEEKDAY(B37)=1,WEEKDAY(B37)=7,C37="日",Q37="祝日",Q37="特休",Q37="代休",Q37="休み"),"休日",IF(C37="","","勤務")))) -> 勤務 | G37: =IF(F37="","",IF(F37=":","",IF(F37>=VALUE("13:15"),IF(F37>VALUE("17:45"),IF(F37>VALUE("21:00"),"1:15","1:00"),"0:45"),0))) | H37: =IF(G37="","",F37-E37-G37)
B38: =IF(B37="","",IF(DAY(B37+1) < 5,"",B37+1)) | C38: =B38 | D38: =IF(B38="","",IF(Q38="勤務","勤務",IF(OR(WEEKDAY(B38)=1,WEEKDAY(B38)=7,C38="日",Q38="祝日",Q38="特休",Q38="代休",Q38="休み"),"休日",IF(C38="","","勤務")))) | G38: =IF(F38="","",IF(F38=":","",IF(F38>=VALUE("13:15"),IF(F38>VALUE("17:45"),IF(F38>VALUE("21:00"),"1:15","1:00"),"0:45"),0))) | H38: =IF(G38="","",F38-E38-G38)
B39: 【備 考】

Sheet マスタ
A1: 就業 | B1: 開 始 | C1: 0.375 | E1: 国民の祝日・休日月日 | F1: 国民の祝日・休日名称 | G1: 曜
B2: 終 了 | C2: 0.73958333 | E2: 45124 | F2: 海の日 | G2: =IF(E2<>"",E2,"") -> 45124
A3: 昼休憩 | B3: 開 始 | C3: 0.5 | E3: 45149 | F3: 山の日 | G3: =IF(E3<>"",E3,"") -> 45149
B4: 終 了 | C4: 0.53125 | E4: 45152 | F4: 顧客(BSW)・夏季休暇 | G4: =IF(E4<>"",E4,"") -> 45152
A5: 休憩時間 | B5: 0 | C5: 0.25 | D5: 未満 | E5: 45153 | F5: 顧客(BSW)・夏季休暇 | G5: =IF(E5<>"",E5,"") -> 45153
B6: 0.03125 | C6: 0.25 | D6: 超 | E6: 45154 | F6: 顧客(BSW)・夏季休暇 | G6: =IF(E6<>"",E6,"") -> 45154
B7: 0.041666667 | C7: 0.33333333 | D7: 超 | E7: 45187 | F7: 敬老の日 | G7: =IF(E7<>"",E7,"") -> 45187
E8: 45192 | F8: 秋分の日 | G8: =IF(E8<>"",E8,"") -> 45192
E9: 45208 | F9: スポーツの日 | G9: =IF(E9<>"",E9,"") -> 45208
E10: 45233 | F10: 文化の日 | G10: =IF(E10<>"",E10,"") -> 45233
E11: 45253 | F11: 勤労感謝の日 | G11: =IF(E11<>"",E11,"") -> 45253
E12: 45288 | F12: 顧客(BSW)年末休暇 | G12: =IF(E12<>"",E12,"") -> 45288
E13: 45289 | F13: 年末休暇 | G13: =IF(E13<>"",E13,"") -> 45289
E14: 45292 | F14: 元日 | G14: =IF(E14<>"",E14,"") -> 45292
E15: 45293 | F15: 年始休暇 | G15: =IF(E15<>"",E15,"") -> 45293
E16: 45294 | F16: 年始休暇 | G16: =IF(E16<>"",E16,"") -> 45294
E17: 45295 | F17: 年始休暇 | G17: =IF(E17<>"",E17,"") -> 45295
E18: 45299 | F18: 成人の日 | G18: =IF(E18<>"",E18,"") -> 45299
E19: 45333 | F19: 建国記念の日 | G19: =IF(E19<>"",E19,"") -> 45333
... E22: 45371 | F22: 春分の日 | G22: =IF(E22<>"",E22,"") -> 45371
G24: =IF(E24<>"",E24,"")
G25: =IF(E25<>"",E25,"")
